Traceback (most recent call last):
  File "/usr/local/lib/python3.7/site-packages/jupyter_cache/executors/utils.py", line 64, in single_nb_execution
    **kwargs,
  File "/usr/local/lib/python3.7/site-packages/nbclient/client.py", line 1305, in execute
    return NotebookClient(nb=nb, resources=resources, km=km, **kwargs).execute()
  File "/usr/local/lib/python3.7/site-packages/jupyter_core/utils/__init__.py", line 98, in wrapped
    return loop.run_until_complete(inner)
  File "/usr/local/lib/python3.7/asyncio/base_events.py", line 587, in run_until_complete
    return future.result()
  File "/usr/local/lib/python3.7/site-packages/nbclient/client.py", line 706, in async_execute
    cell, index, execution_count=self.code_cells_executed + 1
  File "/usr/local/lib/python3.7/site-packages/nbclient/client.py", line 1058, in async_execute_cell
    await self._check_raise_for_error(cell, cell_index, exec_reply)
  File "/usr/local/lib/python3.7/site-packages/nbclient/client.py", line 914, in _check_raise_for_error
    raise CellExecutionError.from_cell_and_msg(cell, exec_reply_content)
nbclient.exceptions.CellExecutionError: An error occurred while executing the following cell:
------------------
import pandas as pd
import numpy as np
from sklearn import datasets
from sklearn.preprocessing import StandardScaler
from sklearn.neighbors import KNeighborsClassifier
from sklearn.feature_selection import SequentialFeatureSelector
------------------


[0;31m---------------------------------------------------------------------------[0m
[0;31mImportError[0m                               Traceback (most recent call last)
[0;32m<ipython-input-1-714b7be05e77>[0m in [0;36m<module>[0;34m[0m
[1;32m      4[0m [0;32mfrom[0m [0msklearn[0m[0;34m.[0m[0mpreprocessing[0m [0;32mimport[0m [0mStandardScaler[0m[0;34m[0m[0;34m[0m[0m
[1;32m      5[0m [0;32mfrom[0m [0msklearn[0m[0;34m.[0m[0mneighbors[0m [0;32mimport[0m [0mKNeighborsClassifier[0m[0;34m[0m[0;34m[0m[0m
[0;32m----> 6[0;31m [0;32mfrom[0m [0msklearn[0m[0;34m.[0m[0mfeature_selection[0m [0;32mimport[0m [0mSequentialFeatureSelector[0m[0;34m[0m[0;34m[0m[0m
[0m
[0;31mImportError[0m: cannot import name 'SequentialFeatureSelector' from 'sklearn.feature_selection' (/usr/local/lib/python3.7/site-packages/sklearn/feature_selection/__init__.py)

